Workbook

Sheet Topic List
A1: Priority Rank | B1: Topic Cluster | C1: Topic Title | D1: Target Keyword | E1: Search Intent | F1: SEO Score | G1: AEO Score | H1: Priority Score | I1: Content Type | J1: AEO Format | K1: Funnel Stage | L1: Estimated Difficulty | M1: Notes
A2: 1 | B2: Signal Chain Mastery | C2: The Complete Guide to Guitar Signal Chain Order — Why It Matters and How to Get It Right | D2: signal chain order guitar | E2: Informational | F2: 9 | G2: 10 | H2: =F2*0.4+G2*0.3+7*0.3 | I2: Definitive guide | J2: FAQ + HowTo schema | K2: Top | L2: High
A3: 2 | B3: Signal Chain Mastery | C3: Overdrive vs Distortion vs Fuzz: The Definitive Guide for Modeler Users | D3: overdrive vs distortion vs fuzz | E3: Informational | F3: 9 | G3: 9 | H3: =F3*0.4+G3*0.3+7*0.3 | I3: Definitive guide | J3: FAQ schema | K3: Top | L3: High
A4: 3 | B4: Signal Chain Mastery | C4: 4-Cable Method Explained: How to Integrate Your Modeler with a Real Amp | D4: 4 cable method guitar | E4: Informational | F4: 8 | G4: 9 | H4: =F4*0.4+G4*0.3+7*0.3 | I4: How-to article | J4: HowTo schema | K4: Middle | L4: Medium
A5: 4 | B5: Signal Chain Mastery | C5: Effects Loop Explained: What It Is and Why You Need One | D5: effects loop guitar explained | E5: Informational | F5: 7 | G5: 9 | H5: =F5*0.4+G5*0.3+7*0.3 | I5: How-to article | J5: FAQ schema | K5: Top | L5: Medium
A6: 5 | B6: Signal Chain Mastery | C6: Gain Staging for Guitar: How to Stack Drives Without Mud | D6: gain staging guitar | E6: Informational | F6: 7 | G6: 8 | H6: =F6*0.4+G6*0.3+7*0.3 | I6: How-to article | J6: HowTo schema | K6: Middle | L6: Medium
A7: 6 | B7: Signal Chain Mastery | C7: Wet/Dry Guitar Rigs: The Complete Routing Guide | D7: wet dry guitar rig | E7: Informational | F7: 6 | G7: 7 | H7: =F7*0.4+G7*0.3+7*0.3 | I7: Definitive guide | J7: HowTo schema | K7: Middle | L7: High
A8: 7 | B8: Signal Chain Mastery | C8: Why Fuzz Pedals Go Before the Wah (And Other Signal Chain Secrets) | D8: fuzz before wah why | E8: Informational | F8: 6 | G8: 8 | H8: =F8*0.4+G8*0.3+7*0.3 | I8: How-to article | J8: FAQ schema | K8: Middle | L8: Low
A9: 8 | B9: Signal Chain Mastery | C9: Buffer vs True Bypass: What Every Pedalboard Needs to Know | D9: buffer vs true bypass guitar | E9: Informational | F9: 7 | G9: 8 | H9: =F9*0.4+G9*0.3+7*0.3 | I9: Comparison post | J9: FAQ schema | K9: Top | L9: Medium
A10: 9 | B10: Signal Chain Mastery | C10: Pre-Amp vs Power Amp: What Each Contributes to Your Tone | D10: preamp vs power amp guitar | E10: Informational | F10: 6 | G10: 9 | H10: =F10*0.4+G10*0.3+7*0.3 | I10: How-to article | J10: FAQ schema | K10: Top | L10: Medium
A11: 10 | B11: Signal Chain Mastery | C11: How to Use Parallel Routing on Your Modeler for Better Tones | D11: parallel routing guitar modeler | E11: Informational | F11: 5 | G11: 6 | H11: =F11*0.4+G11*0.3+7*0.3 | I11: How-to article | J11: HowTo schema | K11: Middle | L11: Medium
A12: 11 | B12: Platform-Specific Guides | C12: Line 6 Helix: Complete Beginner's Guide to Building Your First Preset | D12: helix beginner guide | E12: Informational | F12: 8 | G12: 7 | H12: =F12*0.4+G12*0.3+8*0.3 | I12: Definitive guide | J12: HowTo schema | K12: Top | L12: High
A13: 12 | B13: Platform-Specific Guides | C13: Quad Cortex vs Helix vs Kemper: Which Modeler Is Right for You? | D13: quad cortex vs helix vs kemper | E13: Commercial | F13: 9 | G13: 8 | H13: =F13*0.4+G13*0.3+8*0.3 | I13: Comparison post | J13: Article schema | K13: Middle | L13: High
A14: 13 | B14: Platform-Specific Guides | C14: Boss Katana Hidden Amps: How to Unlock Sneaky Amps via Tone Studio | D14: boss katana hidden amps sneaky amps | E14: Informational | F14: 8 | G14: 7 | H14: =F14*0.4+G14*0.3+8*0.3 | I14: How-to article | J14: HowTo schema | K14: Middle | L14: Medium
A15: 14 | B15: Platform-Specific Guides | C15: Best Helix Amp Models Ranked: Our Top 15 for Every Genre | D15: best helix amp models | E15: Commercial | F15: 9 | G15: 7 | H15: =F15*0.4+G15*0.3+8*0.3 | I15: Listicle | J15: Article schema | K15: Middle | L15: High
A16: 15 | B16: Platform-Specific Guides | C16: Neural DSP Quad Cortex Tips: 10 Things You Didn't Know It Could Do | D16: quad cortex tips tricks | E16: Informational | F16: 7 | G16: 6 | H16: =F16*0.4+G16*0.3+8*0.3 | I16: Listicle | J16: Article schema | K16: Middle | L16: Medium
A17: 16 | B17: Platform-Specific Guides | C17: How to Use Helix Snapshots Like a Pro | D17: helix snapshots guide | E17: Informational | F17: 7 | G17: 7 | H17: =F17*0.4+G17*0.3+8*0.3 | I17: How-to article | J17: HowTo schema | K17: Middle | L17: Medium
A18: 17 | B18: Platform-Specific Guides | C18: Boss Katana vs Helix vs Quad Cortex: Best Modeler Under $1000? | D18: boss katana vs helix vs quad cortex | E18: Commercial | F18: 8 | G18: 7 | H18: =F18*0.4+G18*0.3+8*0.3 | I18: Comparison post | J18: Article schema | K18: Middle | L18: Medium
A19: 18 | B19: Platform-Specific Guides | C19: TONEX vs Helix vs Quad Cortex: AI Capture vs Traditional Modeling | D19: tonex vs helix vs quad cortex | E19: Commercial | F19: 7 | G19: 8 | H19: =F19*0.4+G19*0.3+8*0.3 | I19: Comparison post | J19: FAQ schema | K19: Middle | L19: High
A20: 19 | B20: Platform-Specific Guides | C20: How to Import IRs on Helix, Quad Cortex, and Kemper | D20: import IR helix quad cortex | E20: Informational | F20: 6 | G20: 7 | H20: =F20*0.4+G20*0.3+8*0.3 | I20: How-to article | J20: HowTo schema | K20: Middle | L20: Medium
A21: 20 | B21: Platform-Specific Guides | C21: Fractal FM3 vs Quad Cortex: Which Is Better for Live Use? | D21: fractal fm3 vs quad cortex live | E21: Commercial | F21: 7 | G21: 6 | H21: =F21*0.4+G21*0.3+8*0.3 | I21: Comparison post | J21: Article schema | K21: Middle | L21: Medium
A22: 21 | B22: Artist Tone Breakdowns | C22: How to Get Stevie Ray Vaughan's Tone on Helix | D22: srv tone helix | E22: Informational | F22: 8 | G22: 6 | H22: =F22*0.4+G22*0.3+7*0.3 | I22: How-to article | J22: HowTo schema | K22: Middle | L22: Medium
A23: 22 | B23: Artist Tone Breakdowns | C23: How to Get David Gilmour's Comfortably Numb Solo Tone | D23: david gilmour tone comfortably numb | E23: Informational | F23: 8 | G23: 6 | H23: =F23*0.4+G23*0.3+7*0.3 | I23: How-to article | J23: HowTo schema | K23: Middle | L23: Medium
A24: 23 | B24: Artist Tone Breakdowns | C24: How to Get The Edge's Delay Tone (Dotted Eighth Note Guide) | D24: the edge delay tone dotted eighth | E24: Informational | F24: 7 | G24: 7 | H24: =F24*0.4+G24*0.3+7*0.3 | I24: How-to article | J24: HowTo schema | K24: Middle | L24: Medium
A25: 24 | B25: Artist Tone Breakdowns | C25: How to Get John Mayer's Clean Blues Tone on Any Modeler | D25: john mayer tone modeler | E25: Informational | F25: 7 | G25: 6 | H25: =F25*0.4+G25*0.3+7*0.3 | I25: How-to article | J25: HowTo schema | K25: Middle | L25: Medium
A26: 25 | B26: Artist Tone Breakdowns | C26: How to Get Kurt Cobain's Grunge Tone (It's Simpler Than You Think) | D26: kurt cobain grunge tone | E26: Informational | F26: 7 | G26: 7 | H26: =F26*0.4+G26*0.3+7*0.3 | I26: How-to article | J26: HowTo schema | K26: Middle | L26: Low
A27: 26 | B27: Artist Tone Breakdowns | C27: How to Get Slash's Les Paul Through Marshall Tone | D27: slash tone les paul marshall | E27: Informational | F27: 7 | G27: 6 | H27: =F27*0.4+G27*0.3+7*0.3 | I27: How-to article | J27: HowTo schema | K27: Middle | L27: Medium
A28: 27 | B28: Artist Tone Breakdowns | C28: How to Get Eddie Van Halen's Brown Sound on a Modeler | D28: eddie van halen brown sound modeler | E28: Informational | F28: 7 | G28: 6 | H28: =F28*0.4+G28*0.3+7*0.3 | I28: How-to article | J28: HowTo schema | K28: Middle | L28: Medium
A29: 28 | B29: Artist Tone Breakdowns | C29: How to Get Tom Morello's Guitar Sounds (Kill Switch, Wah Tricks, and More) | D29: tom morello guitar sounds | E29: Informational | F29: 6 | G29: 6 | H29: =F29*0.4+G29*0.3+7*0.3 | I29: How-to article | J29: HowTo schema | K29: Middle | L29: Medium
A30: 29 | B30: Artist Tone Breakdowns | C30: 5 Iconic Guitar Tones You Can Nail in Under 5 Minutes on Helix | D30: iconic guitar tones helix quick | E30: Informational | F30: 7 | G30: 5 | H30: =F30*0.4+G30*0.3+7*0.3 | I30: Listicle | J30: Article schema | K30: Top | L30: Medium
A31: 30 | B31: Artist Tone Breakdowns | C31: The 10 Most-Searched Guitar Tones (And How to Get Them) | D31: most searched guitar tones how to | E31: Informational | F31: 8 | G31: 7 | H31: =F31*0.4+G31*0.3+7*0.3 | I31: Listicle | J31: Article schema | K31: Top | L31: High
A32: 31 | B32: Amp & Cab Science | C32: Fender vs Marshall vs Vox: The 3 Amp Voices Every Guitarist Should Know | D32: fender vs marshall vs vox tone | E32: Informational | F32: 8 | G32: 9 | H32: =F32*0.4+G32*0.3+7*0.3 | I32: Comparison post | J32: FAQ schema | K32: Top | L32: Medium
A33: 32 | B33: Amp & Cab Science | C33: EL34 vs 6L6 Power Tubes: How They Shape Your Amp's Tone | D33: el34 vs 6l6 tone difference | E33: Informational | F33: 6 | G33: 9 | H33: =F33*0.4+G33*0.3+7*0.3 | I33: Comparison post | J33: FAQ schema | K33: Middle | L33: Medium
... A62: 61 | B62: Gear & Buying Guides | C62: Best Budget Modeler 2026: Under $500 Options Ranked | D62: best budget modeler 2026 | E62: Commercial | F62: 8 | G62: 6 | H62: =F62*0.4+G62*0.3+7*0.3 | I62: Listicle | J62: Article schema | K62: Bottom | L62: High
A63: 62 | B63: Gear & Buying Guides | C63: What Is a Tone Recipe? How ToneRecipes Works | D63: what is tone recipe | E63: Informational | F63: 4 | G63: 7 | H63: =F63*0.4+G63*0.3+9*0.3 | I63: How-to article | J63: FAQ schema | K63: Top | L63: Low
A64: 63 | B64: Gear & Buying Guides | C64: Helix vs HX Stomp vs HX Effects: Which Line 6 Board Do You Need? | D64: helix vs hx stomp vs hx effects | E64: Commercial | F64: 8 | G64: 7 | H64: =F64*0.4+G64*0.3+7*0.3 | I64: Comparison post | J64: FAQ schema | K64: Middle | L64: Medium
A65: 64 | B65: Gear & Buying Guides | C65: Neural Amp Modeler (NAM) Explained: Free AI Amp Modeling | D65: neural amp modeler explained | E65: Informational | F65: 7 | G65: 9 | H65: =F65*0.4+G65*0.3+7*0.3 | I65: How-to article | J65: FAQ schema | K65: Top | L65: Medium
A66: 65 | B66: Gear & Buying Guides | C66: Kemper Profiler MK 2 vs Quad Cortex: The 2026 Flagship Showdown | D66: kemper mk2 vs quad cortex 2026 | E66: Commercial | F66: 8 | G66: 6 | H66: =F66*0.4+G66*0.3+7*0.3 | I66: Comparison post | J66: Article schema | K66: Middle | L66: High
A67: 66 | B67: Gear & Buying Guides | C67: Do You Need a Power Amp with Your Modeler? (FRFR vs Power Amp + Cab) | D67: power amp modeler frfr | E67: Commercial | F67: 6 | G67: 7 | H67: =F67*0.4+G67*0.3+7*0.3 | I67: How-to article | J67: FAQ schema | K67: Middle | L67: Medium
A68: 67 | B68: Gear & Buying Guides | C68: Best IRs for Helix: Our Top Picks for Every Genre | D68: best IRs helix | E68: Commercial | F68: 7 | G68: 5 | H68: =F68*0.4+G68*0.3+7*0.3 | I68: Listicle | J68: Article schema | K68: Middle | L68: Medium
...

Sheet Cluster Map
A1: Cluster Name | B1: Pillar Topic | C1: Topic Count | D1: Avg SEO Score | E1: Avg AEO Score | F1: Avg Priority Score | G1: Recommended Priority | H1: Notes
A2: Signal Chain Mastery | B2: The Complete Guide to Guitar Signal Chain Order — Why It Matters and How to Get It Right | C2: 10 | D2: =AVERAGE('Topic List'!F2:F11) | E2: =AVERAGE('Topic List'!G2:G11) | F2: =AVERAGE('Topic List'!H2:H11) | G2: 1 | H2: Highest combined SEO+AEO scores; foundational content
A3: Platform-Specific Guides | B3: Quad Cortex vs Helix vs Kemper: Which Modeler Is Right for You? | C3: 10 | D3: =AVERAGE('Topic List'!F12:F21) | E3: =AVERAGE('Topic List'!G12:G21) | F3: =AVERAGE('Topic List'!H12:H21) | G3: 2 | H3: High commercial intent; drives product-related traffic
A4: Artist Tone Breakdowns | B4: The 10 Most-Searched Guitar Tones (And How to Get Them) | C4: 10 | D4: =AVERAGE('Topic List'!F22:F31) | E4: =AVERAGE('Topic List'!G22:G31) | F4: =AVERAGE('Topic List'!H22:H31) | G4: 3 | H4: High search volume; strong engagement potential
A5: Amp & Cab Science | B5: Fender vs Marshall vs Vox: The 3 Amp Voices Every Guitarist Should Know | C5: 10 | D5: =AVERAGE('Topic List'!F32:F41) | E5: =AVERAGE('Topic List'!G32:G41) | F5: =AVERAGE('Topic List'!H32:H41) | G5: 4 | H5: Strong AEO scores; educational authority builder
A6: Effects Deep Dives | B6: Chorus vs Flanger vs Phaser: The Modulation Effects Explained | C6: 10 | D6: =AVERAGE('Topic List'!F42:F51) | E6: =AVERAGE('Topic List'!G42:G51) | F6: =AVERAGE('Topic List'!H42:H51) | G6: 5 | H6: Strong AEO; evergreen educational content
A7: Modeler Workflow & Live Use | B7: Going Direct to FOH: The Complete Guide for Modeler Users | C7: 10 | D7: =AVERAGE('Topic List'!F52:F61) | E7: =AVERAGE('Topic List'!G52:G61) | F7: =AVERAGE('Topic List'!H52:H61) | G7: 6 | H7: Practical utility; builds user loyalty
A8: Gear & Buying Guides | B8: Best Budget Modeler 2026: Under $500 Options Ranked | C8: 10 | D8: =AVERAGE('Topic List'!F62:F71) | E8: =AVERAGE('Topic List'!G62:G71) | F8: =AVERAGE('Topic List'!H62:H71) | G8: 7 | H8: Commercial intent but time-sensitive; refresh annually

Sheet AEO Quick Wins
A1: Rank | B1: Topic Title | C1: Target Keyword | D1: AEO Score | E1: SEO Score | F1: AI Answer Format | G1: Schema Type | H1: Featured Snippet Opportunity | I1: AI Platform Opportunity | J1: Funnel Stage
A2: 1 | B2: The Complete Guide to Guitar Signal Chain Order — Why It Matters and How to Get It Right | C2: signal chain order guitar | D2: 10 | E2: 9 | F2: Direct Q&A + Step list | G2: FAQ + HowTo schema | H2: Definition box / paragraph | I2: ChatGPT, Perplexity, Google SGE | J2: Top
A3: 2 | B3: What Is an Impulse Response (IR) and Why Does It Matter? | C3: what is impulse response guitar | D3: 10 | E3: 7 | F3: Direct Q&A paragraph | G3: FAQ schema | H3: Step-by-step list / paragraph | I3: ChatGPT, Perplexity, Google SGE | J3: Top
A4: 3 | B4: Overdrive vs Distortion vs Fuzz: The Definitive Guide for Modeler Users | C4: overdrive vs distortion vs fuzz | D4: 9 | E4: 9 | F4: Direct Q&A paragraph | G4: FAQ schema | H4: Definition box / paragraph | I4: ChatGPT, Perplexity, Google SGE | J4: Top
A5: 4 | B5: 4-Cable Method Explained: How to Integrate Your Modeler with a Real Amp | C5: 4 cable method guitar | D5: 9 | E5: 8 | F5: Numbered step list | G5: HowTo schema | H5: Step-by-step list / paragraph | I5: Google SGE, Perplexity | J5: Middle
A6: 5 | B6: Fender vs Marshall vs Vox: The 3 Amp Voices Every Guitarist Should Know | C6: fender vs marshall vs vox tone | D6: 9 | E6: 8 | F6: Direct Q&A paragraph | G6: FAQ schema | H6: Comparison table / list | I6: ChatGPT, Perplexity, Google SGE | J6: Top
A7: 6 | B7: Chorus vs Flanger vs Phaser: The Modulation Effects Explained | C7: chorus vs flanger vs phaser guitar | D7: 9 | E7: 8 | F7: Direct Q&A paragraph | G7: FAQ schema | H7: Comparison table / list | I7: ChatGPT, Perplexity, Google SGE | J7: Top
A8: 7 | B8: Effects Loop Explained: What It Is and Why You Need One | C8: effects loop guitar explained | D8: 9 | E8: 7 | F8: Direct Q&A paragraph | G8: FAQ schema | H8: Step-by-step list / paragraph | I8: ChatGPT, Perplexity, Google SGE | J8: Top
A9: 8 | B9: Delay Types Explained: Analog vs Digital vs Tape | C9: delay types analog digital tape guitar | D9: 9 | E9: 7 | F9: Direct Q&A paragraph | G9: FAQ schema | H9: Step-by-step list / paragraph | I9: ChatGPT, Perplexity, Google SGE | J9: Top
A10: 9 | B10: Reverb Types Explained: Spring vs Plate vs Hall vs Room | C10: reverb types spring plate hall room | D10: 9 | E10: 7 | F10: Direct Q&A paragraph | G10: FAQ schema | H10: Step-by-step list / paragraph | I10: ChatGPT, Perplexity, Google SGE | J10: Top
A11: 10 | B11: Compressor Pedal Explained: What It Does and When to Use One | C11: compressor pedal explained guitar | D11: 9 | E11: 7 | F11: Direct Q&A paragraph | G11: FAQ schema | H11: Step-by-step list / paragraph | I11: ChatGPT, Perplexity, Google SGE | J11: Top
A12: 11 | B12: Neural Amp Modeler (NAM) Explained: Free AI Amp Modeling | C12: neural amp modeler explained | D12: 9 | E12: 7 | F12: Direct Q&A paragraph | G12: FAQ schema | H12: Step-by-step list / paragraph | I12: ChatGPT, Perplexity, Google SGE | J12: Top
A13: 12 | B13: Pre-Amp vs Power Amp: What Each Contributes to Your Tone | C13: preamp vs power amp guitar | D13: 9 | E13: 6 | F13: Direct Q&A paragraph | G13: FAQ schema | H13: Step-by-step list / paragraph | I13: ChatGPT, Perplexity, Google SGE | J13: Top
... A21: 20 | B21: Buffer vs True Bypass: What Every Pedalboard Needs to Know | C21: buffer vs true bypass guitar | D21: 8 | E21: 7 | F21: Direct Q&A paragraph | G21: FAQ schema | H21: Comparison table / list | I21: ChatGPT, Perplexity, Google SGE | J21: Top
